Workbook

Sheet location
A1: locationID | B1: ISO3 | C1: ISO_1 | D1: country_code | E1: location | F1: location_var | G1: gadm1_name | H1: gadm1_var | I1: island | J1: gadm0_name | K1: tdwg4_name | L1: tdwg1 | M1: tdwg1_name | N1: glonaf_country | O1: adm_level | P1: sinas_region | Q1: continent
A2: 1 | B2: ABW | C2: AW | D2: AW | E2: Aruba | I2: 1 | J2: Aruba | K2: Aruba | L2: 8 | M2: Southern America | N2: Aruba | O2: 0 | P2: Central America and the Caribbean | Q2: North America
A3: 2 | B3: AFG | C3: AF | D3: AF | E3: Afghanistan | I3: 0 | J3: Afghanistan | K3: Afghanistan | L3: 3 | M3: Asia-Temperate | N3: Afghanistan | O3: 0 | P3: Western Asia | Q3: Asia
A4: 3 | B4: AGO | C4: AO | D4: AO | E4: Angola | I4: 0 | J4: Angola | K4: Angola | L4: 2 | M4: Africa | N4: Angola | O4: 0 | P4: Sub-Saharan Africa | Q4: Africa
A5: 4 | B5: AIA | C5: AI | D5: AI | E5: Anguilla | F5: Anguilla Island | I5: 1 | J5: Anguilla | K5: Anguilla | L5: 8 | M5: Southern America | N5: Anguilla | O5: 0 | P5: Central America and the Caribbean | Q5: North America
A6: 5 | B6: ALA | C6: AX | D6: AX | E6: Åland | F6: Aland Islands; Åland Islands; �LAND ISLANDS | I6: 1 | J6: Åland | L6: 1 | M6: Europe | O6: 0 | P6: Europe | Q6: Europe
A7: 6 | B7: ALB | C7: AL | D7: AL | E7: Albania | F7: Western Palaearctic Region - Albania | I7: 0 | J7: Albania | K7: Albania | L7: 1 | M7: Europe | N7: Albania | O7: 0 | P7: Europe | Q7: Europe
A8: 7 | B8: AND | C8: AD | D8: AD | E8: Andorra | I8: 0 | J8: Andorra | M8: Europe | O8: 0 | P8: Europe | Q8: Europe
A9: 8 | B9: CUW | C9: CW | D9: CW | E9: Curaçao | F9: Curaçao; Curacao; CuraÃ§ao I.; Curaçao I.; Curacao I. | I9: 1 | J9: Curaçao | K9: Curacao | L9: 8 | M9: Southern America | N9: Netherlands Antilles | O9: 0 | P9: Central America and the Caribbean | Q9: North America
A10: 9 | B10: SXM | C10: SX | D10: SX | E10: Sint Maarten | F10: Sint Maarten (Dutch part); St Maarten (NL) | I10: 1 | J10: Sint Maarten | K10: Netherlands Leeward Is. | L10: 8 | M10: Southern America | N10: Netherlands Antilles | O10: 0 | P10: Central America and the Caribbean | Q10: North America
A11: 10 | B11: ARE | C11: AE | D11: AE | E11: United Arab Emirates | F11: United Arab Em.; the United Arab Emirates | I11: 0 | J11: United Arab Emirates | K11: United Arab Emirates | L11: 3 | M11: Asia-Temperate | N11: United Arab Emirates (the) | O11: 0 | P11: Saharo-Arabia | Q11: Asia
A12: 11 | B12: ARG | C12: AR | D12: AR | E12: Argentina | F12: Argentina Distrito Federal; Argentina Northeast; Argentina Northwest; Argentina South; Argentine | I12: 0 | J12: Argentina | L12: 8 | M12: Southern America | N12: Argentina | O12: 0 | P12: Southern America | Q12: South America
A13: 12 | B13: ARM | C13: AM | D13: AM | E13: Armenia | I13: 0 | J13: Armenia | K13: Armenia | L13: 3 | M13: Asia-Temperate | N13: Armenia | O13: 0 | P13: Western Asia | Q13: Asia
A14: 13 | B14: ASM | C14: AS | D14: AS | E14: American Samoa | I14: 1 | J14: American Samoa | L14: 6 | M14: Pacific | N14: American Samoa | O14: 0 | P14: Pacific | Q14: Oceania
A15: 14 | B15: ATA | C15: AQ | D15: AQ | E15: Antarctica | F15: Brunt Ice Shelf; Adelie Land; East Antarctic Ice Sheet; East Antarctica; Ellsworth Mountains; Enderby Land; Filchner Ice Shelf; Larsen Ice Shelf; North Victoria Land; North-west Antarctic Peninsula; Ross Ice Shelf; South Antarctic Peninsula; South Orkney Islands; South Victoria Land; Transantarctic Mountains | I15: 0 | J15: Antarctica | K15: Antarctica | L15: 9 | M15: Antarctic | N15: Antarctica | O15: 0 | P15: Antarctic | Q15: Antarctica
A16: 15 | B16: ATF | C16: TF | D16: TF | E16: Crozet Islands | F16: Crozet; Crozet Islands Group; Crozet. Is; Îles Crozet; Crozet Is.; Crozet Island Group | I16: 1 | J16: French Southern Territories | L16: 9 | M16: Antarctic | N16: French Southern Territories (the) | O16: 0 | P16: Antarctic | Q16: Antarctica
A17: 16 | B17: ATF | C17: TF | D17: TF | E17: Kerguelen Islands | F17: Kerguelen; Kerguelen Islands (France); Kerguelen Is.; Kerguelen Island | I17: 1 | J17: French Southern Territories | L17: 9 | M17: Antarctic | N17: French Southern Territories (the) | O17: 0 | P17: Antarctic | Q17: Antarctica
A18: 17 | B18: ATF | C18: TF | D18: TF | E18: Scattered Islands | F18: Scattered; Îles Éparses; Glorioso Islands | I18: 1 | J18: French Southern Territories | L18: 9 | M18: Antarctic | N18: French Southern Territories (the) | O18: 0 | P18: Antarctic | Q18: Antarctica
A19: 18 | B19: ATF | C19: TF | D19: TF | E19: St. Paul Island | F19: St Paul I. | I19: 1 | J19: French Southern Territories | L19: 9 | M19: Antarctic | N19: French Southern Territories (the) | O19: 0 | P19: Antarctic | Q19: Antarctica
A20: 19 | B20: ATF | C20: TF | D20: TF | E20: Amsterdam Island | F20: Amsterdam I.; Amsterdam Islands | I20: 1 | J20: French Southern Territories | L20: 9 | M20: Antarctic | N20: French Southern Territories (the) | O20: 0 | P20: Antarctic | Q20: Antarctica
A21: 20 | B21: AUS | C21: AU | D21: AU | E21: Australia | F21: Eastern Australia; South Western Australia; North Western Australia; South Western Australia; Australasian Region - Australia; Autralia | I21: 0 | J21: Australia | L21: 5 | M21: Australasia | N21: Australia | O21: 0 | P21: Australasia | Q21: Oceania
A22: 21 | B22: AUS | C22: AU | D22: AU | E22: Tasmania | F22: Australasian Region - Tasmania; AUSTRALIA Tasmania; Macquarie Island | I22: 1 | J22: Australia | K22: Tasmania | L22: 5 | M22: Australasia | N22: Australia | O22: 0 | P22: Australasia | Q22: Oceania
A23: 22 | B23: AUT | C23: AT | D23: AT | E23: Austria | F23: Western Palaearctic Region - Austria | I23: 0 | J23: Austria | L23: 1 | M23: Europe | N23: Austria | O23: 0 | P23: Europe | Q23: Europe
A24: 23 | B24: AZE | C24: AZ | D24: AZ | E24: Azerbaijan | I24: 0 | J24: Azerbaijan | M24: Asia-Temperate | O24: 0 | P24: Western Asia | Q24: Asia
A25: 24 | B25: BDI | C25: BI | D25: BI | E25: Burundi | I25: 0 | J25: Burundi | K25: Burundi | L25: 2 | M25: Africa | N25: Burundi | O25: 0 | P25: Sub-Saharan Africa | Q25: Africa
A26: 25 | B26: BEL | C26: BE | D26: BE | E26: Belgium | I26: 0 | J26: Belgium | K26: Belgium | L26: 1 | M26: Europe | N26: Belgium | O26: 0 | P26: Europe | Q26: Europe
A27: 26 | B27: BEN | C27: BJ | D27: BJ | E27: Benin | I27: 0 | J27: Benin | K27: Benin | L27: 2 | M27: Africa | N27: Benin | O27: 0 | P27: Sub-Saharan Africa | Q27: Africa
A28: 27 | B28: BES | C28: BQ | D28: BQ | E28: Bonaire | F28: Bonaire (Netherlands) | I28: 1 | J28: Bonaire, Saint Eustatius and Saba | M28: Southern America | O28: 0 | P28: Central America and the Caribbean | Q28: North America
A29: 28 | B29: BES | C29: BQ | D29: BQ | E29: Saba | I29: 1 | J29: Bonaire, Saint Eustatius and Saba | M29: Southern America | O29: 0 | P29: Central America and the Caribbean | Q29: North America
A30: 29 | B30: BES | C30: BQ | D30: BQ | E30: Sint Eustatius | I30: 1 | J30: Bonaire, Saint Eustatius and Saba | M30: Southern America | O30: 0 | P30: Central America and the Caribbean | Q30: North America
A31: 30 | B31: BFA | C31: BF | D31: BF | E31: Burkina Faso | F31: Burkina | I31: 0 | J31: Burkina Faso | K31: Burkina Faso | L31: 2 | M31: Africa | N31: Burkina Faso | O31: 0 | P31: Sub-Saharan Africa | Q31: Africa
A32: 31 | B32: BGD | C32: BD | D32: BD | E32: Bangladesh | I32: 0 | J32: Bangladesh | K32: Bangladesh | L32: 4 | M32: Asia-Tropical | N32: Bangladesh | O32: 0 | P32: Southern Asia | Q32: Asia
A33: 32 | B33: BGR | C33: BG | D33: BG | E33: Bulgaria | I33: 0 | J33: Bulgaria | K33: Bulgaria | L33: 1 | M33: Europe | N33: Bulgaria | O33: 0 | P33: Europe | Q33: Europe
A34: 33 | B34: BHR | C34: BH | D34: BH | E34: Bahrain | I34: 0 | J34: Bahrain | L34: 3 | M34: Asia-Temperate | O34: 0 | P34: Saharo-Arabia | Q34: Asia
A35: 34 | B35: BHS | C35: BS | D35: BS | E35: Bahamas | F35: Bahamas (the); Bahamas, The | I35: 1 | J35: Bahamas | K35: Bahamas | L35: 8 | M35: Southern America | N35: Bahamas (the) | O35: 0 | P35: Central America and the Caribbean | Q35: North America
A36: 35 | B36: BIH | C36: BA | D36: BA | E36: Bosnia and Herzegovina | F36: Bosnia-Herzegovina; Bosnia and Herz.; Bosnia Herzegovina; Bosnia Herzegov.; Bosnia; Bosnia-Hercegovina | I36: 0 | J36: Bosnia and Herzegovina | M36: Europe | O36: 0 | P36: Europe | Q36: Europe
A37: 36 | B37: BLM | C37: BL | D37: BL | E37: Saint-Barthélemy | F37: St Barthélemy; St. Barthélemy; Saint-Barthélemy; Barthelemy; Saint Barthelemy; Saint Barthélemy | I37: 1 | J37: Saint-Barthélemy | K37: St. Martin-St. Barthelemy | L37: 8 | M37: Southern America | N37: Saint Barthelemy | O37: 0 | P37: Central America and the Caribbean | Q37: North America
A38: 37 | B38: BLR | C38: BY | D38: BY | E38: Belarus | F38: Western Palaearctic Region - Belarus | I38: 0 | J38: Belarus | K38: Belarus | L38: 1 | M38: Europe | N38: Belarus | O38: 0 | P38: Europe | Q38: Europe
A39: 38 | B39: BLZ | C39: BZ | D39: BZ | E39: Belize | I39: 0 | J39: Belize | K39: Belize | L39: 8 | M39: Southern America | N39: Belize | O39: 0 | P39: Central America and the Caribbean | Q39: North America
A40: 39 | B40: BMU | C40: BM | D40: BM | E40: Bermuda | F40: Bermuda (United Kingdom) | I40: 1 | J40: Bermuda | K40: Bermuda | L40: 8 | M40: Southern America | N40: Bermuda | O40: 0 | P40: Central America and the Caribbean | Q40: North America
...

Sheet stateProvince
A1: locationID | B1: ISO3 | C1: ISO_1 | D1: country_code | E1: location | F1: location_var | G1: gadm1_name | H1: gadm1_var | I1: island | J1: gadm0_name | K1: tdwg4_name | L1: tdwg1 | M1: tdwg1_name | N1: glonaf_country | O1: adm_level | P1: sinas_region | Q1: continent
A2: 277 | B2: AFG | D2: AF | E2: Afghanistan | F2: =IFERROR(IF(VLOOKUP(E2, location!E$2:F$290, 2, FALSE) = 0, "", VLOOKUP(E2, location!E$2:F$290, 2, FALSE)), "") | G2: Badakhshan | H2: Badahšan | I2: 0 | J2: Afghanistan | K2: Afghanistan | L2: 3 | M2: Asia-Temperate | N2: Afghanistan | O2: 1 | P2: =IFERROR(VLOOKUP(E2, location!$E$2:$P$290, 12, FALSE), "") -> Western Asia | Q2: Asia
A3: 278 | B3: AFG | C3: AF-BDG | D3: AF | E3: Afghanistan | F3: =IFERROR(IF(VLOOKUP(E3, location!E$2:F$290, 2, FALSE) = 0, "", VLOOKUP(E3, location!E$2:F$290, 2, FALSE)), "") | G3: Badghis | H3: Badghes; Badghisat; Badgis | I3: 0 | J3: Afghanistan | K3: Afghanistan | L3: 3 | M3: Asia-Temperate | N3: Afghanistan | O3: 1 | P3: =IFERROR(VLOOKUP(E3, location!$E$2:$P$290, 12, FALSE), "") -> Western Asia | Q3: Asia
A4: 279 | B4: AFG | C4: AF-BGL | D4: AF | E4: Afghanistan | F4: =IFERROR(IF(VLOOKUP(E4, location!E$2:F$290, 2, FALSE) = 0, "", VLOOKUP(E4, location!E$2:F$290, 2, FALSE)), "") | G4: Baghlan | H4: Baglan; Bughlan | I4: 0 | J4: Afghanistan | K4: Afghanistan | L4: 3 | M4: Asia-Temperate | N4: Afghanistan | O4: 1 | P4: =IFERROR(VLOOKUP(E4, location!$E$2:$P$290, 12, FALSE), "") -> Western Asia | Q4: Asia
A5: 280 | B5: AFG | C5: AF-BAL | D5: AF | E5: Afghanistan | F5: =IFERROR(IF(VLOOKUP(E5, location!E$2:F$290, 2, FALSE) = 0, "", VLOOKUP(E5, location!E$2:F$290, 2, FALSE)), "") | G5: Balkh | H5: Balh; Mazar-i-Sharif; Mazar | I5: 0 | J5: Afghanistan | K5: Afghanistan | L5: 3 | M5: Asia-Temperate | N5: Afghanistan | O5: 1 | P5: =IFERROR(VLOOKUP(E5, location!$E$2:$P$290, 12, FALSE), "") -> Western Asia | Q5: Asia
A6: 281 | B6: AFG | C6: AF-BAM | D6: AF | E6: Afghanistan | F6: =IFERROR(IF(VLOOKUP(E6, location!E$2:F$290, 2, FALSE) = 0, "", VLOOKUP(E6, location!E$2:F$290, 2, FALSE)), "") | G6: Bamyan | I6: 0 | J6: Afghanistan | K6: Afghanistan | L6: 3 | M6: Asia-Temperate | N6: Afghanistan | O6: 1 | P6: =IFERROR(VLOOKUP(E6, location!$E$2:$P$290, 12, FALSE), "") -> Western Asia | Q6: Asia
A7: 282 | B7: AFG | C7: AF-DAY | D7: AF | E7: Afghanistan | F7: =IFERROR(IF(VLOOKUP(E7, location!E$2:F$290, 2, FALSE) = 0, "", VLOOKUP(E7, location!E$2:F$290, 2, FALSE)), "") | G7: Daykundi | I7: 0 | J7: Afghanistan | K7: Afghanistan | L7: 3 | M7: Asia-Temperate | N7: Afghanistan | O7: 1 | P7: =IFERROR(VLOOKUP(E7, location!$E$2:$P$290, 12, FALSE), "") -> Western Asia | Q7: Asia
A8: 283 | B8: AFG | C8: AF-FRA | D8: AF | E8: Afghanistan | F8: =IFERROR(IF(VLOOKUP(E8, location!E$2:F$290, 2, FALSE) = 0, "", VLOOKUP(E8, location!E$2:F$290, 2, FALSE)), "") | G8: Farah | I8: 0 | J8: Afghanistan | K8: Afghanistan | L8: 3 | M8: Asia-Temperate | N8: Afghanistan | O8: 1 | P8: =IFERROR(VLOOKUP(E8, location!$E$2:$P$290, 12, FALSE), "") -> Western Asia | Q8: Asia
A9: 284 | B9: AFG | C9: AF-FYB | D9: AF | E9: Afghanistan | F9: =IFERROR(IF(VLOOKUP(E9, location!E$2:F$290, 2, FALSE) = 0, "", VLOOKUP(E9, location!E$2:F$290, 2, FALSE)), "") | G9: Faryab | H9: Fariab; Maimana; Meymaneh | I9: 0 | J9: Afghanistan | K9: Afghanistan | L9: 3 | M9: Asia-Temperate | N9: Afghanistan | O9: 1 | P9: =IFERROR(VLOOKUP(E9, location!$E$2:$P$290, 12, FALSE), "") -> Western Asia | Q9: Asia
A10: 285 | B10: AFG | C10: AF-GHA | D10: AF | E10: Afghanistan | F10: =IFERROR(IF(VLOOKUP(E10, location!E$2:F$290, 2, FALSE) = 0, "", VLOOKUP(E10, location!E$2:F$290, 2, FALSE)), "") | G10: Ghazni | H10: Gazni | I10: 0 | J10: Afghanistan | K10: Afghanistan | L10: 3 | M10: Asia-Temperate | N10: Afghanistan | O10: 1 | P10: =IFERROR(VLOOKUP(E10, location!$E$2:$P$290, 12, FALSE), "") -> Western Asia | Q10: Asia
A11: 286 | B11: AFG | C11: AF-GHO | D11: AF | E11: Afghanistan | F11: =IFERROR(IF(VLOOKUP(E11, location!E$2:F$290, 2, FALSE) = 0, "", VLOOKUP(E11, location!E$2:F$290, 2, FALSE)), "") | G11: Ghor | H11: Gawr; Ghore; Ghour; Ghur | I11: 0 | J11: Afghanistan | K11: Afghanistan | L11: 3 | M11: Asia-Temperate | N11: Afghanistan | O11: 1 | P11: =IFERROR(VLOOKUP(E11, location!$E$2:$P$290, 12, FALSE), "") -> Western Asia | Q11: Asia
A12: 287 | B12: AFG | D12: AF | E12: Afghanistan | F12: =IFERROR(IF(VLOOKUP(E12, location!E$2:F$290, 2, FALSE) = 0, "", VLOOKUP(E12, location!E$2:F$290, 2, FALSE)), "") | G12: Hilmand | H12: Girishk; Hilmend | I12: 0 | J12: Afghanistan | K12: Afghanistan | L12: 3 | M12: Asia-Temperate | N12: Afghanistan | O12: 1 | P12: =IFERROR(VLOOKUP(E12, location!$E$2:$P$290, 12, FALSE), "") -> Western Asia | Q12: Asia
A13: 288 | B13: AFG | D13: AF | E13: Afghanistan | F13: =IFERROR(IF(VLOOKUP(E13, location!E$2:F$290, 2, FALSE) = 0, "", VLOOKUP(E13, location!E$2:F$290, 2, FALSE)), "") | G13: Hirat | I13: 0 | J13: Afghanistan | K13: Afghanistan | L13: 3 | M13: Asia-Temperate | N13: Afghanistan | O13: 1 | P13: =IFERROR(VLOOKUP(E13, location!$E$2:$P$290, 12, FALSE), "") -> Western Asia | Q13: Asia
A14: 289 | B14: AFG | D14: AF | E14: Afghanistan | F14: =IFERROR(IF(VLOOKUP(E14, location!E$2:F$290, 2, FALSE) = 0, "", VLOOKUP(E14, location!E$2:F$290, 2, FALSE)), "") | G14: Jawzjan | H14: Jaozjan; Jozjan; Juzjan; Jouzjan; Sh | I14: 0 | J14: Afghanistan | K14: Afghanistan | L14: 3 | M14: Asia-Temperate | N14: Afghanistan | O14: 1 | P14: =IFERROR(VLOOKUP(E14, location!$E$2:$P$290, 12, FALSE), "") -> Western Asia | Q14: Asia
A15: 290 | B15: AFG | C15: AF-KAB | D15: AF | E15: Afghanistan | F15: =IFERROR(IF(VLOOKUP(E15, location!E$2:F$290, 2, FALSE) = 0, "", VLOOKUP(E15, location!E$2:F$290, 2, FALSE)), "") | G15: Kabul | H15: Cabul; Kabol; Kaboul | I15: 0 | J15: Afghanistan | K15: Afghanistan | L15: 3 | M15: Asia-Temperate | N15: Afghanistan | O15: 1 | P15: =IFERROR(VLOOKUP(E15, location!$E$2:$P$290, 12, FALSE), "") -> Western Asia | Q15: Asia
A16: 291 | B16: AFG | C16: AF-KAN | D16: AF | E16: Afghanistan | F16: =IFERROR(IF(VLOOKUP(E16, location!E$2:F$290, 2, FALSE) = 0, "", VLOOKUP(E16, location!E$2:F$290, 2, FALSE)), "") | G16: Kandahar | H16: Qandahar | I16: 0 | J16: Afghanistan | K16: Afghanistan | L16: 3 | M16: Asia-Temperate | N16: Afghanistan | O16: 1 | P16: =IFERROR(VLOOKUP(E16, location!$E$2:$P$290, 12, FALSE), "") -> Western Asia | Q16: Asia
A17: 292 | B17: AFG | D17: AF | E17: Afghanistan | F17: =IFERROR(IF(VLOOKUP(E17, location!E$2:F$290, 2, FALSE) = 0, "", VLOOKUP(E17, location!E$2:F$290, 2, FALSE)), "") | G17: Kapisa | H17: Kapesa | I17: 0 | J17: Afghanistan | K17: Afghanistan | L17: 3 | M17: Asia-Temperate | N17: Afghanistan | O17: 1 | P17: =IFERROR(VLOOKUP(E17, location!$E$2:$P$290, 12, FALSE), "") -> Western Asia | Q17: Asia
A18: 293 | B18: AFG | C18: AF-KHO | D18: AF | E18: Afghanistan | F18: =IFERROR(IF(VLOOKUP(E18, location!E$2:F$290, 2, FALSE) = 0, "", VLOOKUP(E18, location!E$2:F$290, 2, FALSE)), "") | G18: Khost | I18: 0 | J18: Afghanistan | K18: Afghanistan | L18: 3 | M18: Asia-Temperate | N18: Afghanistan | O18: 1 | P18: =IFERROR(VLOOKUP(E18, location!$E$2:$P$290, 12, FALSE), "") -> Western Asia | Q18: Asia
A19: 294 | B19: AFG | C19: AF-KNR | D19: AF | E19: Afghanistan | F19: =IFERROR(IF(VLOOKUP(E19, location!E$2:F$290, 2, FALSE) = 0, "", VLOOKUP(E19, location!E$2:F$290, 2, FALSE)), "") | G19: Kunar | H19: Konarha; Kunarha | I19: 0 | J19: Afghanistan | K19: Afghanistan | L19: 3 | M19: Asia-Temperate | N19: Afghanistan | O19: 1 | P19: =IFERROR(VLOOKUP(E19, location!$E$2:$P$290, 12, FALSE), "") -> Western Asia | Q19: Asia
A20: 295 | B20: AFG | C20: AF-KDZ | D20: AF | E20: Afghanistan | F20: =IFERROR(IF(VLOOKUP(E20, location!E$2:F$290, 2, FALSE) = 0, "", VLOOKUP(E20, location!E$2:F$290, 2, FALSE)), "") | G20: Kunduz | H20: Kondoz; Qonduz; Qunduz | I20: 0 | J20: Afghanistan | K20: Afghanistan | L20: 3 | M20: Asia-Temperate | N20: Afghanistan | O20: 1 | P20: =IFERROR(VLOOKUP(E20, location!$E$2:$P$290, 12, FALSE), "") -> Western Asia | Q20: Asia
A21: 296 | B21: AFG | C21: AF-LAG | D21: AF | E21: Afghanistan | F21: =IFERROR(IF(VLOOKUP(E21, location!E$2:F$290, 2, FALSE) = 0, "", VLOOKUP(E21, location!E$2:F$290, 2, FALSE)), "") | G21: Laghman | H21: Lagman | I21: 0 | J21: Afghanistan | K21: Afghanistan | L21: 3 | M21: Asia-Temperate | N21: Afghanistan | O21: 1 | P21: =IFERROR(VLOOKUP(E21, location!$E$2:$P$290, 12, FALSE), "") -> Western Asia | Q21: Asia
A22: 297 | B22: AFG | C22: AF-LOG | D22: AF | E22: Afghanistan | F22: =IFERROR(IF(VLOOKUP(E22, location!E$2:F$290, 2, FALSE) = 0, "", VLOOKUP(E22, location!E$2:F$290, 2, FALSE)), "") | G22: Logar | H22: Lawghar; Loghar | I22: 0 | J22: Afghanistan | K22: Afghanistan | L22: 3 | M22: Asia-Temperate | N22: Afghanistan | O22: 1 | P22: =IFERROR(VLOOKUP(E22, location!$E$2:$P$290, 12, FALSE), "") -> Western Asia | Q22: Asia
A23: 298 | B23: AFG | C23: AF-NAN | D23: AF | E23: Afghanistan | F23: =IFERROR(IF(VLOOKUP(E23, location!E$2:F$290, 2, FALSE) = 0, "", VLOOKUP(E23, location!E$2:F$290, 2, FALSE)), "") | G23: Nangarhar | H23: Ningrahar; Eastern Province (Afghanistan) | I23: 0 | J23: Afghanistan | K23: Afghanistan | L23: 3 | M23: Asia-Temperate | N23: Afghanistan | O23: 1 | P23: =IFERROR(VLOOKUP(E23, location!$E$2:$P$290, 12, FALSE), "") -> Western Asia | Q23: Asia
A24: 299 | B24: AFG | C24: AF-NIM | D24: AF | E24: Afghanistan | F24: =IFERROR(IF(VLOOKUP(E24, location!E$2:F$290, 2, FALSE) = 0, "", VLOOKUP(E24, location!E$2:F$290, 2, FALSE)), "") | G24: Nimroz | H24: Neemroze; Nimrod; Nimrooz; Nimroze; | I24: 0 | J24: Afghanistan | K24: Afghanistan | L24: 3 | M24: Asia-Temperate | N24: Afghanistan | O24: 1 | P24: =IFERROR(VLOOKUP(E24, location!$E$2:$P$290, 12, FALSE), "") -> Western Asia | Q24: Asia
A25: 300 | B25: AFG | D25: AF | E25: Afghanistan | F25: =IFERROR(IF(VLOOKUP(E25, location!E$2:F$290, 2, FALSE) = 0, "", VLOOKUP(E25, location!E$2:F$290, 2, FALSE)), "") | G25: Nuristan | H25: Nooristan; Nuristão | I25: 0 | J25: Afghanistan | K25: Afghanistan | L25: 3 | M25: Asia-Temperate | N25: Afghanistan | O25: 1 | P25: =IFERROR(VLOOKUP(E25, location!$E$2:$P$290, 12, FALSE), "") -> Western Asia | Q25: Asia
A26: 301 | B26: AFG | D26: AF | E26: Afghanistan | F26: =IFERROR(IF(VLOOKUP(E26, location!E$2:F$290, 2, FALSE) = 0, "", VLOOKUP(E26, location!E$2:F$290, 2, FALSE)), "") | G26: Paktika | H26: Paktiya; Paktya; Southern Province | I26: 0 | J26: Afghanistan | K26: Afghanistan | L26: 3 | M26: Asia-Temperate | N26: Afghanistan | O26: 1 | P26: =IFERROR(VLOOKUP(E26, location!$E$2:$P$290, 12, FALSE), "") -> Western Asia | Q26: Asia
A27: 302 | B27: AFG | D27: AF | E27: Afghanistan | F27: =IFERROR(IF(VLOOKUP(E27, location!E$2:F$290, 2, FALSE) = 0, "", VLOOKUP(E27, location!E$2:F$290, 2, FALSE)), "") | G27: Paktya | H27: Paktiya; Southern Province | I27: 0 | J27: Afghanistan | K27: Afghanistan | L27: 3 | M27: Asia-Temperate | N27: Afghanistan | O27: 1 | P27: =IFERROR(VLOOKUP(E27, location!$E$2:$P$290, 12, FALSE), "") -> Western Asia | Q27: Asia
A28: 303 | B28: AFG | D28: AF | E28: Afghanistan | F28: =IFERROR(IF(VLOOKUP(E28, location!E$2:F$290, 2, FALSE) = 0, "", VLOOKUP(E28, location!E$2:F$290, 2, FALSE)), "") | G28: Panjshir | I28: 0 | J28: Afghanistan | K28: Afghanistan | L28: 3 | M28: Asia-Temperate | N28: Afghanistan | O28: 1 | P28: =IFERROR(VLOOKUP(E28, location!$E$2:$P$290, 12, FALSE), "") -> Western Asia | Q28: Asia
A29: 304 | B29: AFG | C29: AF-PAR | D29: AF | E29: Afghanistan | F29: =IFERROR(IF(VLOOKUP(E29, location!E$2:F$290, 2, FALSE) = 0, "", VLOOKUP(E29, location!E$2:F$290, 2, FALSE)), "") | G29: Parwan | H29: Charikar | I29: 0 | J29: Afghanistan | K29: Afghanistan | L29: 3 | M29: Asia-Temperate | N29: Afghanistan | O29: 1 | P29: =IFERROR(VLOOKUP(E29, location!$E$2:$P$290, 12, FALSE), "") -> Western Asia | Q29: Asia
A30: 305 | B30: AFG | C30: AF-SAM | D30: AF | E30: Afghanistan | F30: =IFERROR(IF(VLOOKUP(E30, location!E$2:F$290, 2, FALSE) = 0, "", VLOOKUP(E30, location!E$2:F$290, 2, FALSE)), "") | G30: Samangan | I30: 0 | J30: Afghanistan | K30: Afghanistan | L30: 3 | M30: Asia-Temperate | N30: Afghanistan | O30: 1 | P30: =IFERROR(VLOOKUP(E30, location!$E$2:$P$290, 12, FALSE), "") -> Western Asia | Q30: Asia
A31: 306 | B31: AFG | D31: AF | E31: Afghanistan | F31: =IFERROR(IF(VLOOKUP(E31, location!E$2:F$290, 2, FALSE) = 0, "", VLOOKUP(E31, location!E$2:F$290, 2, FALSE)), "") | G31: Sari Pul | H31: Sar-e Pul; Saripol | I31: 0 | J31: Afghanistan | K31: Afghanistan | L31: 3 | M31: Asia-Temperate | N31: Afghanistan | O31: 1 | P31: =IFERROR(VLOOKUP(E31, location!$E$2:$P$290, 12, FALSE), "") -> Western Asia | Q31: Asia
A32: 307 | B32: AFG | C32: AF-TAK | D32: AF | E32: Afghanistan | F32: =IFERROR(IF(VLOOKUP(E32, location!E$2:F$290, 2, FALSE) = 0, "", VLOOKUP(E32, location!E$2:F$290, 2, FALSE)), "") | G32: Takhar | H32: Takar | I32: 0 | J32: Afghanistan | K32: Afghanistan | L32: 3 | M32: Asia-Temperate | N32: Afghanistan | O32: 1 | P32: =IFERROR(VLOOKUP(E32, location!$E$2:$P$290, 12, FALSE), "") -> Western Asia | Q32: Asia
A33: 308 | B33: AFG | C33: AF-URU | D33: AF | E33: Afghanistan | F33: =IFERROR(IF(VLOOKUP(E33, location!E$2:F$290, 2, FALSE) = 0, "", VLOOKUP(E33, location!E$2:F$290, 2, FALSE)), "") | G33: Uruzgan | H33: Urozgan | I33: 0 | J33: Afghanistan | K33: Afghanistan | L33: 3 | M33: Asia-Temperate | N33: Afghanistan | O33: 1 | P33: =IFERROR(VLOOKUP(E33, location!$E$2:$P$290, 12, FALSE), "") -> Western Asia | Q33: Asia
A34: 309 | B34: AFG | D34: AF | E34: Afghanistan | F34: =IFERROR(IF(VLOOKUP(E34, location!E$2:F$290, 2, FALSE) = 0, "", VLOOKUP(E34, location!E$2:F$290, 2, FALSE)), "") | G34: Wardak | H34: Verdak; Wardag; Maiden | I34: 0 | J34: Afghanistan | K34: Afghanistan | L34: 3 | M34: Asia-Temperate | N34: Afghanistan | O34: 1 | P34: =IFERROR(VLOOKUP(E34, location!$E$2:$P$290, 12, FALSE), "") -> Western Asia | Q34: Asia
A35: 310 | B35: AFG | D35: AF | E35: Afghanistan | F35: =IFERROR(IF(VLOOKUP(E35, location!E$2:F$290, 2, FALSE) = 0, "", VLOOKUP(E35, location!E$2:F$290, 2, FALSE)), "") | G35: Zabul | H35: Zubul; Zaboul | I35: 0 | J35: Afghanistan | K35: Afghanistan | L35: 3 | M35: Asia-Temperate | N35: Afghanistan | O35: 1 | P35: =IFERROR(VLOOKUP(E35, location!$E$2:$P$290, 12, FALSE), "") -> Western Asia | Q35: Asia
A36: 311 | B36: AGO | C36: AO-BGO | D36: AO | E36: Angola | F36: =IFERROR(IF(VLOOKUP(E36, location!E$2:F$290, 2, FALSE) = 0, "", VLOOKUP(E36, location!E$2:F$290, 2, FALSE)), "") | G36: Bengo | I36: 0 | J36: Angola | K36: Angola | L36: 2 | M36: Africa | N36: Angola | O36: 1 | P36: =IFERROR(VLOOKUP(E36, location!$E$2:$P$290, 12, FALSE), "") -> Sub-Saharan Africa | Q36: Africa
A37: 312 | B37: AGO | C37: AO-BGU | D37: AO | E37: Angola | F37: =IFERROR(IF(VLOOKUP(E37, location!E$2:F$290, 2, FALSE) = 0, "", VLOOKUP(E37, location!E$2:F$290, 2, FALSE)), "") | G37: Benguela | H37: Benguella | I37: 0 | J37: Angola | K37: Angola | L37: 2 | M37: Africa | N37: Angola | O37: 1 | P37: =IFERROR(VLOOKUP(E37, location!$E$2:$P$290, 12, FALSE), "") -> Sub-Saharan Africa | Q37: Africa
A38: 313 | B38: AGO | D38: AO | E38: Angola | F38: =IFERROR(IF(VLOOKUP(E38, location!E$2:F$290, 2, FALSE) = 0, "", VLOOKUP(E38, location!E$2:F$290, 2, FALSE)), "") | G38: Bié | I38: 0 | J38: Angola | K38: Angola | L38: 2 | M38: Africa | N38: Angola | O38: 1 | P38: =IFERROR(VLOOKUP(E38, location!$E$2:$P$290, 12, FALSE), "") -> Sub-Saharan Africa | Q38: Africa
A39: 314 | B39: AGO | C39: AO-CAB | D39: AO | E39: Angola | F39: =IFERROR(IF(VLOOKUP(E39, location!E$2:F$290, 2, FALSE) = 0, "", VLOOKUP(E39, location!E$2:F$290, 2, FALSE)), "") | G39: Cabinda | I39: 0 | J39: Angola | K39: Angola | L39: 2 | M39: Africa | N39: Angola | O39: 1 | P39: =IFERROR(VLOOKUP(E39, location!$E$2:$P$290, 12, FALSE), "") -> Sub-Saharan Africa | Q39: Africa
A40: 315 | B40: AGO | C40: AO-CCU | D40: AO | E40: Angola | F40: =IFERROR(IF(VLOOKUP(E40, location!E$2:F$290, 2, FALSE) = 0, "", VLOOKUP(E40, location!E$2:F$290, 2, FALSE)), "") | G40: Cuando Cubango | I40: 0 | J40: Angola | K40: Angola | L40: 2 | M40: Africa | N40: Angola | O40: 1 | P40: =IFERROR(VLOOKUP(E40, location!$E$2:$P$290, 12, FALSE), "") -> Sub-Saharan Africa | Q40: Africa
...
